{
 "cells": [
  {
   "cell_type": "markdown",
   "id": "52313fc6-2a29-410a-b335-a03384e2a9a1",
   "metadata": {},
   "source": [
    "## Exception handling-1\n",
    "\n",
    "\n"
   ]
  },
  {
   "cell_type": "markdown",
   "id": "770997a2-8909-4488-ae3e-1269a59dc4e2",
   "metadata": {},
   "source": [
    "**Q1. What is an Exception in python? Write the difference between Exceptions and Syntax errors.**"
   ]
  },
  {
   "cell_type": "markdown",
   "id": "3bfcce5c-4b79-491e-b68f-49503a88e651",
   "metadata": {},
   "source": [
    "In Python, an exception is an event that occurs during the execution of a program that disrupts the normal flow of the program's instructions. Exceptions are raised when errors occur, such as when a program tries to divide by zero, access an index out of range in a list, or when an object is not callable. When an exception occurs, the normal flow of the program is interrupted and the program terminates unless the exception is handled properly.\n",
    "\n",
    "Handling exceptions in Python involves the use of try-except blocks. A try-block contains the code that might raise an exception. An except-block contains the code that will be executed if an exception occurs in the try-block. The syntax for handling an exception in Python is:"
   ]
  },
  {
   "cell_type": "code",
   "execution_count": 1,
   "id": "d1c59ca0-9200-4e48-971b-21c45ec4a34b",
   "metadata": {},
   "outputs": [
    {
     "name": "stdout",
     "output_type": "stream",
     "text": [
      "A exception occourd\n"
     ]
    }
   ],
   "source": [
    "try:\n",
    "    print(x)\n",
    "except:\n",
    "    print(\"A exception occourd\")"
   ]
  },
  {
   "cell_type": "markdown",
   "id": "e0ed1c87-e757-4900-8268-9a27d8898820",
   "metadata": {},
   "source": [
    "Exceptions and syntax errors are two different types of errors that can occur in a Python program.\n",
    "\n",
    "Syntax errors occur when the code is not properly written according to the rules of the Python language. For example, if we forget to close a parenthesis or if we use the wrong indentation, we will get a syntax error. Syntax errors are detected by the Python interpreter when we run the code, and they prevent the code from running.\n",
    "\n",
    "Exceptions, on the other hand, occur when the code is properly written syntax-wise but still encounters an error while running. Exceptions are raised when an error occurs during the execution of the code, such as when we try to divide by zero, access an index out of range in a list, or when an object is not callable. Unlike syntax errors, exceptions can be handled in our code, allowing the program to continue running even if an error has occurred.\n",
    "\n",
    "In short, syntax errors prevent our code from running and must be fixed before the code can be executed, while exceptions are runtime errors that can be handled and dealt with in our code."
   ]
  },
  {
   "cell_type": "markdown",
   "id": "ef91edde-cd13-414d-b563-60cf5053c6c3",
   "metadata": {},
   "source": [
    "**Q2. What happens when an exception is not handled? Explain with an example.**"
   ]
  },
  {
   "cell_type": "markdown",
   "id": "53f699cd-2182-4a5b-9e06-d17706bf2e90",
   "metadata": {},
   "source": [
    "When an exception is not handled, the program terminates immediately, and the Python interpreter outputs an error message to the console indicating what went wrong. This error message includes the type of the exception, the line number where the exception occurred, and a description of the exception. The error message is known as a traceback and provides information about the cause of the exception.\n",
    "\n",
    "Here is an example of what the traceback might look like when an exception occurs:"
   ]
  },
  {
   "cell_type": "code",
   "execution_count": 2,
   "id": "ee120e58-678c-4cb6-9b24-3b9a35a9929b",
   "metadata": {},
   "outputs": [
    {
     "ename": "ZeroDivisionError",
     "evalue": "division by zero",
     "output_type": "error",
     "traceback": [
      "\u001b[1;31m---------------------------------------------------------------------------\u001b[0m",
      "\u001b[1;31mZeroDivisionError\u001b[0m                         Traceback (most recent call last)",
      "Cell \u001b[1;32mIn[2], line 1\u001b[0m\n\u001b[1;32m----> 1\u001b[0m result \u001b[38;5;241m=\u001b[39m \u001b[38;5;241;43m10\u001b[39;49m\u001b[43m \u001b[49m\u001b[38;5;241;43m/\u001b[39;49m\u001b[43m \u001b[49m\u001b[38;5;241;43m0\u001b[39;49m\n",
      "\u001b[1;31mZeroDivisionError\u001b[0m: division by zero"
     ]
    }
   ],
   "source": [
    "result = 10 / 0"
   ]
  },
  {
   "cell_type": "markdown",
   "id": "7b43a01f-a057-45c2-86c6-756795d84521",
   "metadata": {},
   "source": [
    "In this example, the traceback reports that a ZeroDivisionError occurred. The traceback is generated by the Python interpreter and gives us a view of the call stack, which show the sequence of function calls that led to the exception.\n",
    "\n",
    "When an exception is not handled, the program terminates, and any subsequent code in the program is not executed. This can lead to unexpected results and cause your program to produce incorrect output. To prevent this from happening, it is best to handle exceptions in your our by using try-except blocks."
   ]
  },
  {
   "cell_type": "markdown",
   "id": "0cf632d4-af3e-43ae-9afc-6203afe32584",
   "metadata": {},
   "source": [
    "**Q3. Which Python statements are used to catch and handle exceptions? Explain with an example.**"
   ]
  },
  {
   "cell_type": "markdown",
   "id": "b805e1e9-4861-47c0-b4b5-123d337f6558",
   "metadata": {},
   "source": [
    "In Python, the try and except statements are used to catch and handle exceptions. The try statement is used to enclose the code that might raise an exception. The except statement is used to catch and handle the exception if one occurs.\n",
    "\n",
    "Here is an example of using the try and except statements to catch and handle an exception:"
   ]
  },
  {
   "cell_type": "code",
   "execution_count": 3,
   "id": "538a7913-ab0b-4d58-bec3-409d321a2364",
   "metadata": {},
   "outputs": [
    {
     "name": "stdout",
     "output_type": "stream",
     "text": [
      "Cannot divide by zero!\n"
     ]
    }
   ],
   "source": [
    "try:\n",
    "    result = 10 / 0\n",
    "except ZeroDivisionError:\n",
    "    print(\"Cannot divide by zero!\")"
   ]
  },
  {
   "cell_type": "markdown",
   "id": "8844bdce-850e-4532-bb4d-8ca8a25a33cc",
   "metadata": {},
   "source": [
    "In this example, the code in the try block attempts to divide 10 by 0, which will raise a ZeroDivisionError. The except block catches this exception and outputs an error message indicating that the division by zero is not allowed."
   ]
  },
  {
   "cell_type": "markdown",
   "id": "f3703ca3-604e-4ada-8b62-123f7cee57da",
   "metadata": {},
   "source": [
    "**Q4. Explain with an example:**\n",
    "\n",
    "**a. try and else**\n",
    "\n",
    "**b. finally**\n",
    "\n",
    "**c. raise**"
   ]
  },
  {
   "cell_type": "markdown",
   "id": "d992102b-8f1b-4a9a-a296-e4e85a0db00b",
   "metadata": {},
   "source": [
    "In Python, we can use the else clause in combination with the try statement to specify a block of code that will be executed only if no exception occurs in the try block. The else block is executed after the try block, but only if no exception was raised in the try block. Here is an example of using the try and else statements:"
   ]
  },
  {
   "cell_type": "code",
   "execution_count": 4,
   "id": "086a49dd-3d38-4c96-8e0a-d9aec745af2b",
   "metadata": {},
   "outputs": [
    {
     "name": "stdout",
     "output_type": "stream",
     "text": [
      "5.0\n"
     ]
    }
   ],
   "source": [
    "try:\n",
    "    result = 10 / 2\n",
    "except ZeroDivisionError:\n",
    "    print(\"Cannot divide by zero!\")\n",
    "else:\n",
    "    print(result)"
   ]
  },
  {
   "cell_type": "markdown",
   "id": "e49c3b77-c6c0-4afc-b5a7-f50fb56619c7",
   "metadata": {},
   "source": [
    "In this example, the code in the try block attempts to divide 10 by 2, which will not raise an exception. As a result, the code in the else block will be executed, and the result of the division will be output."
   ]
  },
  {
   "cell_type": "code",
   "execution_count": null,
   "id": "a0b581be-3b2b-415c-843a-964bf5fa04a3",
   "metadata": {},
   "outputs": [],
   "source": []
  },
  {
   "cell_type": "markdown",
   "id": "9523f9c9-cabc-455e-ac61-9174b177c1c0",
   "metadata": {},
   "source": [
    "In Python, we can use the finally clause in combination with the try statement to specify a block of code that will be executed no matter what. The finally block is executed after the try and except blocks, and its purpose is to ensure that certain operations are performed, regardless of whether an exception was raised or not.\n",
    "\n",
    "Here is an example of using the try, except, and finally statements:"
   ]
  },
  {
   "cell_type": "code",
   "execution_count": 5,
   "id": "da9064c6-5989-4402-b1c5-9fd870bd3af8",
   "metadata": {},
   "outputs": [
    {
     "name": "stdout",
     "output_type": "stream",
     "text": [
      "5.0\n",
      "This block of code will always be executed.\n"
     ]
    }
   ],
   "source": [
    "try:\n",
    "    result = 10 / 2\n",
    "except ZeroDivisionError:\n",
    "    print(\"Cannot divide by zero!\")\n",
    "else:\n",
    "    print(result)\n",
    "finally:\n",
    "    print(\"This block of code will always be executed.\")"
   ]
  },
  {
   "cell_type": "markdown",
   "id": "f06a5719-d43c-4da5-bc26-5f0125a2495d",
   "metadata": {},
   "source": [
    "In this example, the code in the try block attempts to divide 10 by 2, which will not raise an exception. As a result, the code in the else block will be executed, and the result of the division will be output. Regardless of whether an exception was raised or not, the code in the finally block will be executed, and the message \"This block of code will always be executed.\" will be output."
   ]
  },
  {
   "cell_type": "code",
   "execution_count": null,
   "id": "e0a75ebc-12d6-4551-93e8-e3d170ec7e00",
   "metadata": {},
   "outputs": [],
   "source": []
  },
  {
   "cell_type": "markdown",
   "id": "048d083e-403e-44e8-8ef8-6480bf356624",
   "metadata": {},
   "source": [
    "In Python, we can use the raise statement to raise an exception manually. Raising an exception means to interrupt the normal flow of control and immediately transfer the execution to an exception handler.\n",
    "\n",
    "Here is an example of using the raise statement to raise an exception:"
   ]
  },
  {
   "cell_type": "code",
   "execution_count": 6,
   "id": "f1f1a871-75f2-41ea-b0de-b472d618a758",
   "metadata": {},
   "outputs": [
    {
     "name": "stdout",
     "output_type": "stream",
     "text": [
      "Cannot divide by zero.\n"
     ]
    }
   ],
   "source": [
    "def divide(a, b):\n",
    "    if b == 0:\n",
    "        raise ZeroDivisionError(\"Cannot divide by zero.\")\n",
    "    return a / b\n",
    "\n",
    "try:\n",
    "    result = divide(10, 0)\n",
    "except ZeroDivisionError as e:\n",
    "    print(e)"
   ]
  },
  {
   "cell_type": "markdown",
   "id": "97db8421-8d3b-49d1-b1a8-7f72f58f295a",
   "metadata": {},
   "source": [
    "In this example, the function divide takes two arguments, a and b, and returns the result of a / b. If b is equal to zero, the raise statement raises a ZeroDivisionError with the message \"Cannot divide by zero.\". The code in the try block calls the divide function with arguments 10 and 0, which will raise a ZeroDivisionError. The except block catches this exception and outputs the error message."
   ]
  },
  {
   "cell_type": "markdown",
   "id": "dccc2815-90e3-40e5-babc-881b5e3f3c03",
   "metadata": {},
   "source": [
    "**Q5. What are Custom Exceptions in python? Why do we need Custom Exceptions? Explain with an example.**"
   ]
  },
  {
   "cell_type": "code",
   "execution_count": null,
   "id": "e5578287-7d8e-4a87-99ef-5afb3a37ad53",
   "metadata": {},
   "outputs": [],
   "source": []
  },
  {
   "cell_type": "markdown",
   "id": "ea0626ce-d87e-47bb-9dc9-3ec0a75a1383",
   "metadata": {},
   "source": [
    "**Q6. Create a custom exception class. Use this class to handle an exception.**"
   ]
  },
  {
   "cell_type": "code",
   "execution_count": null,
   "id": "736d9ebc-4e5c-422f-ae16-164948e0881b",
   "metadata": {},
   "outputs": [],
   "source": []
  }
 ],
 "metadata": {
  "kernelspec": {
   "display_name": "Python 3 (ipykernel)",
   "language": "python",
   "name": "python3"
  },
  "language_info": {
   "codemirror_mode": {
    "name": "ipython",
    "version": 3
   },
   "file_extension": ".py",
   "mimetype": "text/x-python",
   "name": "python",
   "nbconvert_exporter": "python",
   "pygments_lexer": "ipython3",
   "version": "3.10.9"
  }
 },
 "nbformat": 4,
 "nbformat_minor": 5
}
